2020-05-31 08:15:34 WARNING (MainThread) [homeassistant.loader] You are using a custom integration for sony which has not been tested by Home Assistant. This component might cause stability problems, be sure to disable it if you experience issues with Home Assistant.
2020-05-31 08:17:04 ERROR (SyncWorker_17) [sonyapilib.device] HTTPError: HTTPConnectionPool(host='192.168.0.10', port=52323): Max retries exceeded with url: /dmr.xml (Caused by ConnectTimeoutError(<urllib3.connection.HTTPConnection object at 0x7ff632c81b90>, 'Connection to 192.168.0.10 timed out. (connect timeout=5)'))
2020-05-31 08:17:04 ERROR (SyncWorker_17) [sonyapilib.device] Failed to get DMR
2020-05-31 08:17:04 ERROR (MainThread) [homeassistant.components.websocket_api.http.connection.140695391159056] Failed to read action list from device.
Traceback (most recent call last):
  File "/usr/src/homeassistant/homeassistant/components/websocket_api/commands.py", line 130, in handle_call_service
    connection.context(msg),
  File "/usr/src/homeassistant/homeassistant/core.py", line 1253, in async_call
    task.result()
  File "/usr/src/homeassistant/homeassistant/core.py", line 1288, in _execute_service
    await handler.func(service_call)
  File "/usr/src/homeassistant/homeassistant/components/configurator/__init__.py", line 235, in async_handle_service_call
    await self.hass.async_add_job(callback, call.data.get(ATTR_FIELDS, {}))
  File "/usr/local/lib/python3.7/concurrent/futures/thread.py", line 57, in run
    result = self.fn(*self.args, **self.kwargs)
  File "/config/custom_components/sony/media_player.py", line 151, in sony_configuration_callback
    register_result = sony_device.register()
  File "/usr/local/lib/python3.7/site-packages/sonyapilib/device.py", line 575, in register
    "register")
  File "/usr/local/lib/python3.7/site-packages/sonyapilib/device.py", line 492, in _get_action
    raise ValueError('Failed to read action list from device.')
ValueError: Failed to read action list from device.
